# 异步调用修复总结

## 问题发现

在运行过程中出现了新的错误：
```
AttributeError: 'coroutine' object has no attribute 'get'
```

## 问题分析

错误发生在 `agent.py` 第497行：
```python
final_data = result_state.get("final_data")
```

**根本原因**: 在 `run()` 方法中调用了异步方法 `_run_with_checkpoints()`，但缺少了 `await` 关键字，导致返回的是coroutine对象而不是实际的字典结果。

## 修复方案

### 修改位置
`python/sight_server/core/agent.py` 第365行：

**修复前**:
```python
result_state = self._run_with_checkpoints(initial_state)  # type: ignore
```

**修复后**:
```python
result_state = await self._run_with_checkpoints(initial_state)  # type: ignore
```

## 技术要点

1. **异步方法调用**: 当调用 `async def` 方法时，必须使用 `await` 关键字
2. **返回类型**: 没有 `await` 时返回的是coroutine对象，而不是实际的结果
3. **错误表现**: coroutine对象没有 `get()` 方法，导致 `AttributeError`

## 验证结果

- ✅ 基础Python导入功能正常
- ✅ 语法检查通过
- ✅ 异步调用问题已解决

这个修复确保了异步方法的正确调用，避免了coroutine对象被当作字典使用的错误。